Traceback (most recent call last):
  File "/Users/eddifying/micromamba/envs/seaocn_env/lib/python3.8/site-packages/jupyter_cache/executors/utils.py", line 58, in single_nb_execution
    executenb(
  File "/Users/eddifying/micromamba/envs/seaocn_env/lib/python3.8/site-packages/nbclient/client.py", line 1305, in execute
    return NotebookClient(nb=nb, resources=resources, km=km, **kwargs).execute()
  File "/Users/eddifying/micromamba/envs/seaocn_env/lib/python3.8/site-packages/jupyter_core/utils/__init__.py", line 165, in wrapped
    return loop.run_until_complete(inner)
  File "/Users/eddifying/micromamba/envs/seaocn_env/lib/python3.8/asyncio/base_events.py", line 616, in run_until_complete
    return future.result()
  File "/Users/eddifying/micromamba/envs/seaocn_env/lib/python3.8/site-packages/nbclient/client.py", line 705, in async_execute
    await self.async_execute_cell(
  File "/Users/eddifying/micromamba/envs/seaocn_env/lib/python3.8/site-packages/nbclient/client.py", line 1058, in async_execute_cell
    await self._check_raise_for_error(cell, cell_index, exec_reply)
  File "/Users/eddifying/micromamba/envs/seaocn_env/lib/python3.8/site-packages/nbclient/client.py", line 914, in _check_raise_for_error
    raise CellExecutionError.from_cell_and_msg(cell, exec_reply_content)
nbclient.exceptions.CellExecutionError: An error occurred while executing the following cell:
------------------
# Try to combine all the nc files
for ii in ctd_nc:
    ds = xr.open_dataset(ii)
    
    latstn[qdo] = ds.LATITUDE
    lonstn[qdo] = ds.LONGITUDE
    tmp1 = datetime.fromisoformat(ds.datetime)
    mdates1[qdo] = mdates.date2num(tmp1)
    cstart = re.search("Cast", ii).start()
    castnum[qdo] = int(ii[cstart+4:-3])

#    if qdo==0:
#        allctd = ds
#    else:
#        allctd = xr.concat([allctd, ds], "castnum", fill_value=np.nan)
           
    qdo+=1
------------------


[0;31m---------------------------------------------------------------------------[0m
[0;31mIndexError[0m                                Traceback (most recent call last)
Cell [0;32mIn[4], line 5[0m
[1;32m      2[0m [38;5;28;01mfor[39;00m ii [38;5;129;01min[39;00m ctd_nc:
[1;32m      3[0m     ds [38;5;241m=[39m xr[38;5;241m.[39mopen_dataset(ii)
[0;32m----> 5[0m     [43mlatstn[49m[43m[[49m[43mqdo[49m[43m][49m [38;5;241m=[39m ds[38;5;241m.[39mLATITUDE
[1;32m      6[0m     lonstn[qdo] [38;5;241m=[39m ds[38;5;241m.[39mLONGITUDE
[1;32m      7[0m     tmp1 [38;5;241m=[39m datetime[38;5;241m.[39mfromisoformat(ds[38;5;241m.[39mdatetime)

[0;31mIndexError[0m: index 110 is out of bounds for axis 0 with size 110

